2024-08-14 06:27:27 | INFO    | __main__:stash:131 | run - {'image': '20231121', 'version': '0.10.1.post2', 'role': 'EpicPlayer', 'headless': True}
2024-08-14 06:27:38 | INFO    | __main__:claim_epic_games:97 | Try to flush cookie - {'task': 'claim_epic_games'}
2024-08-14 06:27:41 | INFO    | epic_games.agent:_login:237 | login-with-email - {'url': 'https://www.epicgames.com/id/login?lang=en-US&noHostRedirect=true&redirectUrl=https://store.epicgames.com/en-US/free-games&__cf_chl_rt_tk=67tJTGtTXDSiwhkk79FBnR4hW6QYTkfnBOFeMW5ot_8-1723588060-0.0.1.1-5546'}
2024-08-14 06:28:11 | WARNING    | epic_games.agent:authorize:266 | 执行超时 - {'task': 'authorize', 'retry': 0}
2024-08-14 06:28:13 | INFO    | epic_games.agent:_login:237 | login-with-email - {'url': 'https://www.epicgames.com/id/login?lang=en-US&noHostRedirect=true&redirectUrl=https://store.epicgames.com/en-US/free-games&__cf_chl_rt_tk=O2.HmTEBjpcEo8v4N3qjzvWB5CgKFx69p.AS7Cga1.8-1723588093-0.0.1.1-6442'}
2024-08-14 06:28:43 | WARNING    | epic_games.agent:authorize:266 | 执行超时 - {'task': 'authorize', 'retry': 1}
2024-08-14 06:28:45 | INFO    | epic_games.agent:_login:237 | login-with-email - {'url': 'https://www.epicgames.com/id/login?lang=en-US&noHostRedirect=true&redirectUrl=https://store.epicgames.com/en-US/free-games&__cf_chl_rt_tk=RMVZhkkLteCEPTLZ5QTLr.ZV75dOJpkVYApCxxfKWKw-1723588125-0.0.1.1-6463'}
2024-08-14 06:29:15 | WARNING    | epic_games.agent:authorize:266 | 执行超时 - {'task': 'authorize', 'retry': 2}
2024-08-14 06:29:15 | ERROR    | __main__:run:158 | An error has been caught in function 'run', process 'MainProcess' (3722), thread 'MainThread' (140145984334720): - {}
Traceback (most recent call last):
  File "/home/runner/work/aaa/aaa/epic/src/claim.py", line 162, in <module>
    asyncio.run(run())
  File "/opt/hostedtoolcache/Python/3.10.14/x64/lib/python3.10/asyncio/runners.py", line 44, in run
    return loop.run_until_complete(main)
  File "/opt/hostedtoolcache/Python/3.10.14/x64/lib/python3.10/asyncio/base_events.py", line 636, in run_until_complete
    self.run_forever()
  File "/opt/hostedtoolcache/Python/3.10.14/x64/lib/python3.10/asyncio/base_events.py", line 603, in run_forever
    self._run_once()
  File "/opt/hostedtoolcache/Python/3.10.14/x64/lib/python3.10/asyncio/base_events.py", line 1909, in _run_once
    handle._run()
  File "/opt/hostedtoolcache/Python/3.10.14/x64/lib/python3.10/asyncio/events.py", line 80, in _run
    self._context.run(self._callback, *self._args)
> File "/home/runner/work/aaa/aaa/epic/src/claim.py", line 158, in run
    await agent.stash()
  File "/home/runner/work/aaa/aaa/epic/src/claim.py", line 151, in stash
    await self.claim_epic_games(context)
  File "/home/runner/work/aaa/aaa/epic/src/claim.py", line 98, in claim_epic_games
    if await epic.authorize(page):
  File "/home/runner/work/aaa/aaa/epic/src/epic_games/agent.py", line 269, in authorize
    raise RuntimeError(f"Failed to flush token - agent={self.__class__.__name__}")
RuntimeError: Failed to flush token - agent=EpicGames
