2024-10-16 06:30:07 | INFO    | __main__:stash:131 | run - {'image': '20231121', 'version': '0.10.1.post2', 'role': 'EpicPlayer', 'headless': True}
2024-10-16 06:30:15 | INFO    | __main__:claim_epic_games:97 | Try to flush cookie - {'task': 'claim_epic_games'}
2024-10-16 06:30:17 | INFO    | epic_games.agent:_login:237 | login-with-email - {'url': 'https://www.epicgames.com/id/login?lang=en-US&noHostRedirect=true&redirectUrl=https://store.epicgames.com/en-US/free-games&__cf_chl_rt_tk=iqZuMxjXVJhb9ja7xH_J0yAt5TsRH4SJg2051dxN2_k-1729031417-1.0.1.1-z4.QuvT37BgOWTHE1S00XCr1lrE.R7QwPD93fS96.4I'}
2024-10-16 06:30:47 | WARNING    | epic_games.agent:authorize:266 | 执行超时 - {'task': 'authorize', 'retry': 0}
2024-10-16 06:30:50 | INFO    | epic_games.agent:_login:237 | login-with-email - {'url': 'https://www.epicgames.com/id/login?lang=en-US&noHostRedirect=true&redirectUrl=https://store.epicgames.com/en-US/free-games&__cf_chl_rt_tk=7hBjXogeT.TkH3_55JWZG_HLmg1HewBaut0AHPqg9x0-1729031450-1.0.1.1-3z75gDpwscUQVBJonBSl_A46.DXGEN1iTj31fCduLQg'}
2024-10-16 06:31:20 | WARNING    | epic_games.agent:authorize:266 | 执行超时 - {'task': 'authorize', 'retry': 1}
2024-10-16 06:31:22 | INFO    | epic_games.agent:_login:237 | login-with-email - {'url': 'https://www.epicgames.com/id/login?lang=en-US&noHostRedirect=true&redirectUrl=https://store.epicgames.com/en-US/free-games&__cf_chl_rt_tk=obnD5gb3pYnUioFEHcPL4.25Dj08TGVoZwnYFHdf_sM-1729031482-1.0.1.1-st4NFsI3.VXlYbAn28IdZOegfN0n4YxWHrAj3GUbJEw'}
2024-10-16 06:31:52 | WARNING    | epic_games.agent:authorize:266 | 执行超时 - {'task': 'authorize', 'retry': 2}
2024-10-16 06:31:52 | ERROR    | __main__:run:158 | An error has been caught in function 'run', process 'MainProcess' (3437), thread 'MainThread' (140658159901568): - {}
Traceback (most recent call last):
  File "/home/runner/work/aaa/aaa/epic/src/claim.py", line 162, in <module>
    asyncio.run(run())
  File "/opt/hostedtoolcache/Python/3.10.15/x64/lib/python3.10/asyncio/runners.py", line 44, in run
    return loop.run_until_complete(main)
  File "/opt/hostedtoolcache/Python/3.10.15/x64/lib/python3.10/asyncio/base_events.py", line 636, in run_until_complete
    self.run_forever()
  File "/opt/hostedtoolcache/Python/3.10.15/x64/lib/python3.10/asyncio/base_events.py", line 603, in run_forever
    self._run_once()
  File "/opt/hostedtoolcache/Python/3.10.15/x64/lib/python3.10/asyncio/base_events.py", line 1909, in _run_once
    handle._run()
  File "/opt/hostedtoolcache/Python/3.10.15/x64/lib/python3.10/asyncio/events.py", line 80, in _run
    self._context.run(self._callback, *self._args)
> File "/home/runner/work/aaa/aaa/epic/src/claim.py", line 158, in run
    await agent.stash()
  File "/home/runner/work/aaa/aaa/epic/src/claim.py", line 151, in stash
    await self.claim_epic_games(context)
  File "/home/runner/work/aaa/aaa/epic/src/claim.py", line 98, in claim_epic_games
    if await epic.authorize(page):
  File "/home/runner/work/aaa/aaa/epic/src/epic_games/agent.py", line 269, in authorize
    raise RuntimeError(f"Failed to flush token - agent={self.__class__.__name__}")
RuntimeError: Failed to flush token - agent=EpicGames
